#include <stdexcept>

void foo() {
    throw std::runtime_error("failed");
}